TESTS WITH ERRORS 
test13_BFS_Hanoi_02 (gradingtests.UnitTests)
Traceback (most recent call last):
  File "C:\Users\kille\academics\automatedgradingapp\app\testing\uninformed-solvers\gradingtests.py", line 52, in runPlayXSteps
    results = self.pool.apply_async(self.playXSteps, [solver, plays]).get(timeout)
  File "C:\Program Files\Python37\lib\multiprocessing\pool.py", line 679, in get
    raise TimeoutError
multiprocessing.context.TimeoutError

During handling of the above exception, another exception occurred:

Traceback (most recent call last):
  File "C:\Users\kille\academics\automatedgradingapp\app\testing\uninformed-solvers\gradingtests.py", line 296, in test13_BFS_Hanoi_02
    [23, ((5,), (4,), (1, 2, 3))],
  File "C:\Users\kille\academics\automatedgradingapp\app\testing\uninformed-solvers\gradingtests.py", line 57, in runPlayXSteps
    raise Exception("Timed out: %s" % inspect.stack()[1][3])
Exception: Timed out: test13_BFS_Hanoi_02

test14_BFS_Hanoi_03 (gradingtests.UnitTests)
Traceback (most recent call last):
  File "C:\Users\kille\academics\automatedgradingapp\app\testing\uninformed-solvers\gradingtests.py", line 52, in runPlayXSteps
    results = self.pool.apply_async(self.playXSteps, [solver, plays]).get(timeout)
  File "C:\Program Files\Python37\lib\multiprocessing\pool.py", line 679, in get
    raise TimeoutError
multiprocessing.context.TimeoutError

During handling of the above exception, another exception occurred:

Traceback (most recent call last):
  File "C:\Users\kille\academics\automatedgradingapp\app\testing\uninformed-solvers\gradingtests.py", line 314, in test14_BFS_Hanoi_03
    [23, ((1, 4, 5), (), (2, 3))],
  File "C:\Users\kille\academics\automatedgradingapp\app\testing\uninformed-solvers\gradingtests.py", line 57, in runPlayXSteps
    raise Exception("Timed out: %s" % inspect.stack()[1][3])
Exception: Timed out: test14_BFS_Hanoi_03

-------------------------------
TESTS FAILED  
test07_GM_8Puzzle_03 (gradingtests.UnitTests)
Traceback (most recent call last):
  File "C:\Users\kille\academics\automatedgradingapp\app\testing\uninformed-solvers\gradingtests.py", line 175, in test07_GM_8Puzzle_03
    self.assertEqual(p8.getGameState(), ((5,1,4), (6,-1,8), (7,3,2)))
AssertionError: Tuples differ: ((5, 4, -1), (6, 1, 8), (7, 3, 2)) != ((5, 1, 4), (6, -1, 8), (7, 3, 2))

First differing element 0:
(5, 4, -1)
(5, 1, 4)

- ((5, 4, -1), (6, 1, 8), (7, 3, 2))
?       ----

+ ((5, 1, 4), (6, -1, 8), (7, 3, 2))
?      +++        +


test12_BFS_Hanoi_01 (gradingtests.UnitTests)
Traceback (most recent call last):
  File "C:\Users\kille\academics\automatedgradingapp\app\testing\uninformed-solvers\gradingtests.py", line 278, in test12_BFS_Hanoi_01
    [22, ((2,), (3,), (1,))],
  File "C:\Users\kille\academics\automatedgradingapp\app\testing\uninformed-solvers\gradingtests.py", line 55, in runPlayXSteps
    self.assertEqual(results[index], expected)
AssertionError: Tuples differ: ((1, 3), (), (2,)) != ((), (3,), (1, 2))

First differing element 0:
(1, 3)
()

- ((1, 3), (), (2,))
+ ((), (3,), (1, 2))

-------------------------------
TESTS SKIPPED 
-------------------------------
